<?xml version="1.0" ?>
<!-- =================================================================================== -->
<!-- |    This document was autogenerated by xacro from relife-model.xacro             | -->
<!-- |    EDITING THIS FILE BY HAND IS NOT RECOMMENDED                                 | -->
<!-- =================================================================================== -->
<robot name="relife">
  <transmission name="rightwheel_transmission">
    <plugin>transmission_interface/SimpleTransmission</plugin>
    <actuator name="rightwheel_motor" role="actuator_right"/>
    <joint name="RightWheel_link_joint" role="joint_right">
      <mechanical_reduction>1.0</mechanical_reduction>
    </joint>
  </transmission>
  <transmission name="leftwheel_transmission">
    <plugin>transmission_interface/SimpleTransmission</plugin>
    <actuator name="leftwheel_motor" role="actuator_left"/>
    <joint name="LeftWheel_link_joint" role="joint_left">
      <mechanical_reduction>1.0</mechanical_reduction>
    </joint>
  </transmission>
  <!-- <gazebo reference="FrontWheel_link_joint">
        <mu1>1000000000000000.0</mu1>
        <mu2>1000000000000000.0</mu2>
        <kp>1000000000000.0</kp>
        <kd>10.0</kd>
        <minDepth>0.001</minDepth>
        <maxVel>0.1</maxVel>
        <fdir1>1 0 0</fdir1>
    </gazebo> -->
  <gazebo reference="RightWheel_link_joint">
    <mu1>1000000000000000.0</mu1>
    <mu2>1000000000000000.0</mu2>
    <kp>1000000000000.0</kp>
    <kd>10.0</kd>
    <minDepth>0.001</minDepth>
    <maxVel>0.1</maxVel>
    <fdir1>1 0 0</fdir1>
  </gazebo>
  <gazebo reference="LeftWheel_link_joint">
    <mu1>1000000000000000.0</mu1>
    <mu2>1000000000000000.0</mu2>
    <kp>1000000000000.0</kp>
    <kd>10.0</kd>
    <minDepth>0.001</minDepth>
    <maxVel>0.1</maxVel>
    <fdir1>1 0 0</fdir1>
  </gazebo>
  <!-- <gazebo reference="BackWheel_link_joint">
        <mu1>1000000000000000.0</mu1>
        <mu2>1000000000000000.0</mu2>
        <kp>1000000000000.0</kp>
        <kd>10.0</kd>
        <minDepth>0.001</minDepth>
        <maxVel>0.1</maxVel>
        <fdir1>1 0 0</fdir1>
    </gazebo> -->
  <gazebo>
    <plugin filename="libgazebo_ros2_control.so" name="gazebo_ros2_control">
      <!-- <ros2_control type="system" name="GazeboSystem"> -->
      <!-- <robot_namespace>/</robot_namespace> -->
      <robot_param>robot_description</robot_param>
      <robot_param_node>robot_state_publisher</robot_param_node>
      <parameters>/home/iprod/re4life_ws/install/re4life_controller/share/re4life_controller/config/re4life_controllers.yaml</parameters>
      <!-- </ros2_control> -->
    </plugin>
  </gazebo>
  <ros2_control name="RobotSystem" type="system">
    <hardware>
      <plugin>
                gazebo_ros2_control/GazeboSystem
            </plugin>
    </hardware>
    <joint name="RightWheel_link_joint">
      <command_interface name="velocity">
        <param name="min">-1</param>
        <param name="max">1</param>
      </command_interface>
      <state_interface name="position"/>
      <state_interface name="velocity"/>
    </joint>
    <joint name="LeftWheel_link_joint">
      <command_interface name="velocity">
        <param name="min">-1</param>
        <param name="max">1</param>
      </command_interface>
      <state_interface name="position"/>
      <state_interface name="velocity"/>
    </joint>
  </ros2_control>
  <link name="base_link">
    <inertial>
      <mass value="1.0"/>
      <origin rpy="0 0 0" xyz="0 0 0"/>
      <inertia ixx="0.1" ixy="0" ixz="0" iyy="0.1" iyz="0" izz="0.1"/>
    </inertial>
  </link>
  <link name="Body_link">
    <collision name="CenterWheelExtention_collision">
      <origin rpy="0.0 1.42294 0.0" xyz="0.17482 -0.00088 0.15732"/>
      <geometry>
        <mesh filename="package://re4life_robot_description/meshes/Cylinder.001.dae" scale="0.00883 0.00889 0.10297"/>
      </geometry>
    </collision>
    <inertial>
      <inertia ixx="44.2477" ixy="-0.75396" ixz="-9.16026" iyy="61.24271" iyz="-0.57135" izz="42.90716"/>
      <origin rpy="0.0 0.0 0.0" xyz="0.00000 0.00000 -0.00000"/>
      <mass value="0.96"/>
    </inertial>
    <visual name="Root">
      <origin rpy="0.0 1.42294 0.0" xyz="0.17482 -0.00088 0.15732"/>
      <material name="Material.001"/>
      <geometry>
        <mesh filename="package://re4life_robot_description/meshes/Cylinder.001.dae" scale="0.00883 0.00889 0.10297"/>
      </geometry>
    </visual>
  </link>
  <joint name="base_to_body" type="fixed">
    <parent link="base_link"/>
    <child link="Body_link"/>
    <origin rpy="0 0 0" xyz="0 0 0"/>
  </joint>
  <joint name="BackWheel_link_joint" type="continuous">
    <limit effort="2.4" lower="0" upper="0" velocity="1.0"/>
    <origin rpy="1.5708 0.0 -0.13475" xyz="-0.45842 0.00285 0.06126"/>
    <parent link="Body_link"/>
    <child link="BackWheel_link"/>
    <axis xyz="0.0 0.0 1.0"/>
  </joint>
  <joint name="FrontWheel_link_joint" type="continuous">
    <limit effort="2.4" lower="0" upper="0" velocity="1.0"/>
    <origin rpy="0.62698 -1.55961 0.94292" xyz="0.17030 0.00221 0.04710"/>
    <parent link="Body_link"/>
    <child link="FrontWheel_link"/>
    <axis xyz="0.0 0.0 1.0"/>
  </joint>
  <joint name="LeftWheel_link_joint" type="continuous">
    <limit effort="2.4" lower="0" upper="0" velocity="1.0"/>
    <origin rpy="1.5708 0.0 -0.13475" xyz="-0.24508 0.28586 0.04478"/>
    <parent link="Body_link"/>
    <child link="LeftWheel_link"/>
    <axis xyz="0.0 0.0 1.0"/>
  </joint>
  <joint name="RightWheel_link_joint" type="continuous">
    <limit effort="2.4" lower="0" upper="0" velocity="1.0"/>
    <origin rpy="1.57084 -1.13165 0.08268" xyz="-0.24533 -0.28065 0.04553"/>
    <parent link="Body_link"/>
    <child link="RightWheel_link"/>
    <axis xyz="0.0 0.0 1.0"/>
  </joint>
  <joint name="camera_joint" type="fixed">
    <origin rpy="0.0 1.5708 0.0" xyz="0.19112 0.00194 0.54940"/>
    <parent link="Body_link"/>
    <child link="camera"/>
  </joint>
  <joint name="ultrasonic_link_joint" type="fixed">
    <limit effort="30" lower="-3" upper="3" velocity="1"/>
    <origin rpy="3.1035 1.21463 3.01659" xyz="0.23943 -0.00200 0.04405"/>
    <parent link="Body_link"/>
    <child link="ultrasonic_link"/>
  </joint>
  <!-- Define links -->
  <link name="BackWheel_link">
    <collision name="BackWheel_collision">
      <origin rpy="-1.55259 0.13352 0.13597" xyz="0.0 0.0 0.0"/>
      <geometry>
        <mesh filename="package://re4life_robot_description/meshes/Front_end.012.dae" scale="0.0026 0.0026 0.0026"/>
      </geometry>
    </collision>
    <inertial>
      <inertia ixx="0.90769" ixy="0.00012" ixz="-0.00013" iyy="1.73757" iyz="-0.00007" izz="0.90757"/>
      <origin rpy="0.0 0.0 0.0" xyz="0.00977 -0.00502 0.00438"/>
      <mass value="0.96"/>
    </inertial>
    <visual name="BackWheel">
      <origin rpy="-1.55259 0.13352 0.13597" xyz="0.0 0.0 0.0"/>
      <material name="Backdrop.011"/>
      <geometry>
        <mesh filename="package://re4life_robot_description/meshes/Front_end.012.dae" scale="0.0026 0.0026 0.0026"/>
      </geometry>
    </visual>
  </link>
  <link name="FrontWheel_link">
    <collision name="FrontWheel_collision">
      <origin rpy="1.57071 -0.0025 0.01562" xyz="0.0 0.0 0.0"/>
      <geometry>
        <mesh filename="package://re4life_robot_description/meshes/Front_end.011.dae" scale="0.0026 0.0026 0.0026"/>
      </geometry>
    </collision>
    <inertial>
      <inertia ixx="0.90761" ixy="0.00086" ixz="-0.00014" iyy="1.73754" iyz="-0.00555" izz="0.90769"/>
      <origin rpy="0.0 0.0 0.0" xyz="0.00826 0.00633 -0.00563"/>
      <mass value="0.96"/>
    </inertial>
    <visual name="FrontWheel">
      <origin rpy="1.57071 -0.0025 0.01562" xyz="0.0 0.0 0.0"/>
      <material name="Backdrop.010"/>
      <geometry>
        <mesh filename="package://re4life_robot_description/meshes/Front_end.011.dae" scale="0.0026 0.0026 0.0026"/>
      </geometry>
    </visual>
  </link>
  <link name="LeftWheel_link">
    <collision name="LeftWheel_collision">
      <origin rpy="-1.55259 0.13352 0.13597" xyz="0.0 0.0 0.0"/>
      <geometry>
        <mesh filename="package://re4life_robot_description/meshes/Front_end.014.dae" scale="0.0026 0.0026 0.0026"/>
      </geometry>
    </collision>
    <inertial>
      <inertia ixx="0.90769" ixy="0.00012" ixz="-0.00013" iyy="1.73757" iyz="-0.00007" izz="0.90757"/>
      <origin rpy="0.0 0.0 0.0" xyz="0.00977 -0.00502 0.00438"/>
      <mass value="0.96"/>
    </inertial>
    <visual name="LeftWheel">
      <origin rpy="-1.55259 0.13352 0.13597" xyz="0.0 0.0 0.0"/>
      <material name="Backdrop.013"/>
      <geometry>
        <mesh filename="package://re4life_robot_description/meshes/Front_end.014.dae" scale="0.0026 0.0026 0.0026"/>
      </geometry>
    </visual>
  </link>
  <link name="RightWheel_link">
    <collision name="RightWheel_collision">
      <origin rpy="-1.58195 -0.08196 -0.99644" xyz="0.0 0.0 0.0"/>
      <geometry>
        <mesh filename="package://re4life_robot_description/meshes/Front_end.013.dae" scale="0.0026 0.0026 0.0026"/>
      </geometry>
    </collision>
    <inertial>
      <inertia ixx="0.90769" ixy="0.00012" ixz="-0.00013" iyy="1.73757" iyz="-0.00007" izz="0.90757"/>
      <origin rpy="0.0 0.0 0.0" xyz="0.00977 -0.00502 0.00438"/>
      <mass value="0.96"/>
    </inertial>
    <visual name="RightWheel">
      <origin rpy="-1.55259 0.13352 1.37498" xyz="0.0 0.0 0.0"/>
      <material name="Backdrop.012"/>
      <geometry>
        <mesh filename="package://re4life_robot_description/meshes/Front_end.013.dae" scale="0.0026 0.0026 0.0026"/>
      </geometry>
    </visual>
  </link>
  <link name="camera">
    <sensor name="Camera" type="camera">
      <origin rpy="0.0 0.0 0.0" xyz="0.0 0.0 0.0"/>
      <parent link="camera"/>
      <camera>
        <image>
          <width>640</width>
          <height>480</height>
          <hfov>1.5708</hfov>
        </image>
      </camera>
    </sensor>
    <visual name="HelmetGlass">
      <origin rpy="0.0 -1.5708 0.0" xyz="0.53582 0.00004 -0.03632"/>
      <material name="Material.003"/>
      <geometry>
        <mesh filename="package://re4life_robot_description/meshes/Cube.004.dae" scale="0.02382 0.02382 0.02382"/>
      </geometry>
    </visual>
  </link>
  <link name="ultrasonic_link">
    <visual name="ultrasonic">
      <origin rpy="0.0 0.0 0.0" xyz="0.0 0.0 0.0"/>
      <geometry>
        <box size="0.00334 0.00396 0.00339"/>
      </geometry>
    </visual>
  </link>
  <!-- Define materials -->
  <material name="Backdrop.010">
    <color rgba="0.0 0.0 0.0 1.0"/>
  </material>
  <material name="Backdrop.011">
    <color rgba="0.0 0.0 0.0 1.0"/>
  </material>
  <material name="Backdrop.012">
    <color rgba="0.0 0.0 0.0 1.0"/>
  </material>
  <material name="Backdrop.013">
    <color rgba="0.0 0.0 0.0 1.0"/>
  </material>
  <material name="Material.001">
    <color rgba="0.10588 0.10588 0.10588 1.0"/>
  </material>
  <material name="Material.003">
    <color rgba="0.10588 0.10588 0.10588 1.0"/>
  </material>
</robot>
